Workbook

Sheet Initiative List
A1: Item # | B1: Initiative | C1: Discipline | D1: Category | E1: Deliverable | F1: Action | G1: Assigned To | H1: Reviewer | I1: Status | J1: Notes | K1: Priority | L1: Due Date | M1: Priority Weight | N1: Manual Progress % | O1: Effective Progress % | P1: Weighted Earned | Q1: Status Bucket | R1: Overdue Flag | S1: This Week Earned | T1: Last Updated | U1: Week Ending | V1: Due Quarter Bucket
A2: =IF(A1="Item #",1,A1+1) -> 1 | B2: Consistency Workshop | C2: E&I Department | D2: Estimating | E2: Estimate Basis | F2: Develop an Estimate Basis that applies to projects that don’t have a client design criteria. "how Kieiwt OGC does projects" | G2: Ahmad Yakuba | H2: Allen Douglas | I2: Started | J2: build before, during Consistancy Workshops Homer City This is needed for Mock Procjects as well | K2: High | M2: =IF(K2="Critical",4,IF(K2="High",3,IF(K2="Medium",2,IF(K2="Low",1,0)))) -> 3 | N2: 0.25 | O2: =IF(N2="",IF(I2="Closed Out",1,IF(I2="Complete",1,IF(I2="Approved",1,IF(I2="Reviewed",1,IF(I2="In Review",0.9,IF(I2="75% Complete",0.75,IF(I2="50% Complete",0.5,IF(I2="25% Complete",0.25,IF(I2="Started",0.25,0))))))))),MAX(IF(I2="Closed Out",1,IF(I2="Complete",1,IF(I2="Approved",1,IF(I2="Reviewed",1,IF(I2="In Review",0.9,IF(I2="75% Complete",0.75,IF(I2="50% Complete",0.5,IF(I2="25% Complete",0.25,IF(I2="Started",0.25,0))))))))),N2)) -> 0.25 | P2: =M2*O2 -> 0.75 | Q2: =IF(OR(I2="Closed Out",I2="Complete",I2="Approved",I2="Reviewed"),"Closed",IF(OR(I2="HOLD",I2="Pause"),"Blocked","Open")) -> Open | R2: =IF(AND(Q2="Open",ISNUMBER(L2),L2<TODAY()),1,0) -> 0 | S2: 0 | V2: =IF(ISNUMBER(L2),"Q"&ROUNDUP(MONTH(L2)/3,0),IF(LEFT(TRIM(CLEAN(L2)),1)="Q","Q"&VALUE(RIGHT(TRIM(CLEAN(L2)),1)),"No Date")) -> No Date
A3: =IF(A2="Item #",1,A2+1) -> 2 | B3: Estimate Document Numbering | C3: OGC | D3: Document Control | E3: Teambinder Numbering | F3: Apply TeamBinder Document Numbering to Rock County (E&I) | G3: Allen Douglas | I3: HOLD | J3: Need to finish before Department Meeting Friday 4/24 if possible | K3: High | L3: HOLD | M3: =IF(K3="Critical",4,IF(K3="High",3,IF(K3="Medium",2,IF(K3="Low",1,0)))) -> 3 | N3: 0 | O3: =IF(N3="",IF(I3="Closed Out",1,IF(I3="Complete",1,IF(I3="Approved",1,IF(I3="Reviewed",1,IF(I3="In Review",0.9,IF(I3="75% Complete",0.75,IF(I3="50% Complete",0.5,IF(I3="25% Complete",0.25,IF(I3="Started",0.25,0))))))))),MAX(IF(I3="Closed Out",1,IF(I3="Complete",1,IF(I3="Approved",1,IF(I3="Reviewed",1,IF(I3="In Review",0.9,IF(I3="75% Complete",0.75,IF(I3="50% Complete",0.5,IF(I3="25% Complete",0.25,IF(I3="Started",0.25,0))))))))),N3)) -> 0 | P3: =M3*O3 -> 0 | Q3: =IF(OR(I3="Closed Out",I3="Complete",I3="Approved",I3="Reviewed"),"Closed",IF(OR(I3="HOLD",I3="Pause"),"Blocked","Open")) -> Blocked | R3: =IF(AND(Q3="Open",ISNUMBER(L3),L3<TODAY()),1,0) -> 0 | S3: 0 | V3: =IF(ISNUMBER(L3),"Q"&ROUNDUP(MONTH(L3)/3,0),IF(LEFT(TRIM(CLEAN(L3)),1)="Q","Q"&VALUE(RIGHT(TRIM(CLEAN(L3)),1)),"No Date")) -> No Date
A4: =IF(A3="Item #",1,A3+1) -> 3 | B4: Estimate Document Numbering | C4: OGC | D4: Document Control | E4: Teambinder Numbering | F4: Show Rock County Example to Department Managers | G4: Allen Douglas | I4: HOLD | J4: Must complete Item 2 - Rock County Numbering | K4: High | L4: HOLD | M4: =IF(K4="Critical",4,IF(K4="High",3,IF(K4="Medium",2,IF(K4="Low",1,0)))) -> 3 | N4: 0 | O4: =IF(N4="",IF(I4="Closed Out",1,IF(I4="Complete",1,IF(I4="Approved",1,IF(I4="Reviewed",1,IF(I4="In Review",0.9,IF(I4="75% Complete",0.75,IF(I4="50% Complete",0.5,IF(I4="25% Complete",0.25,IF(I4="Started",0.25,0))))))))),MAX(IF(I4="Closed Out",1,IF(I4="Complete",1,IF(I4="Approved",1,IF(I4="Reviewed",1,IF(I4="In Review",0.9,IF(I4="75% Complete",0.75,IF(I4="50% Complete",0.5,IF(I4="25% Complete",0.25,IF(I4="Started",0.25,0))))))))),N4)) -> 0 | P4: =M4*O4 -> 0 | Q4: =IF(OR(I4="Closed Out",I4="Complete",I4="Approved",I4="Reviewed"),"Closed",IF(OR(I4="HOLD",I4="Pause"),"Blocked","Open")) -> Blocked | R4: =IF(AND(Q4="Open",ISNUMBER(L4),L4<TODAY()),1,0) -> 0 | S4: 0 | V4: =IF(ISNUMBER(L4),"Q"&ROUNDUP(MONTH(L4)/3,0),IF(LEFT(TRIM(CLEAN(L4)),1)="Q","Q"&VALUE(RIGHT(TRIM(CLEAN(L4)),1)),"No Date")) -> No Date
A5: =IF(A4="Item #",1,A4+1) -> 4 | B5: Indicative Tool | C5: Instrumentation and Controls | D5: Estimating | E5: Indicative Tool | F5: Developing high-level quantities for instrumentation, controls and Telecoms for ammonia plants, to add it to the indicative procedure and data source. | G5: John McGoldrick | I5: Closed Out | J5: ETA expected by May 1st. Not fisnihed yet due to commitments with Texas LNG estimate changes. TLNG holding up progress (at 75%) | K5: Critical | L5: 42505 | M5: =IF(K5="Critical",4,IF(K5="High",3,IF(K5="Medium",2,IF(K5="Low",1,0)))) -> 4 | N5: 1 | O5: =IF(N5="",IF(I5="Closed Out",1,IF(I5="Complete",1,IF(I5="Approved",1,IF(I5="Reviewed",1,IF(I5="In Review",0.9,IF(I5="75% Complete",0.75,IF(I5="50% Complete",0.5,IF(I5="25% Complete",0.25,IF(I5="Started",0.25,0))))))))),MAX(IF(I5="Closed Out",1,IF(I5="Complete",1,IF(I5="Approved",1,IF(I5="Reviewed",1,IF(I5="In Review",0.9,IF(I5="75% Complete",0.75,IF(I5="50% Complete",0.5,IF(I5="25% Complete",0.25,IF(I5="Started",0.25,0))))))))),N5)) -> 1 | P5: =M5*O5 -> 4 | Q5: =IF(OR(I5="Closed Out",I5="Complete",I5="Approved",I5="Reviewed"),"Closed",IF(OR(I5="HOLD",I5="Pause"),"Blocked","Open")) -> Closed | R5: =IF(AND(Q5="Open",ISNUMBER(L5),L5<TODAY()),1,0) -> 0 | S5: 0 | V5: =IF(ISNUMBER(L5),"Q"&ROUNDUP(MONTH(L5)/3,0),IF(LEFT(TRIM(CLEAN(L5)),1)="Q","Q"&VALUE(RIGHT(TRIM(CLEAN(L5)),1)),"No Date")) -> Q2
A6: =IF(A5="Item #",1,A5+1) -> 5 | B6: Initiatives - Future | C6: Electrical | D6: Procurement | E6: OGC Estimate Checklist | F6: Electrical Checklist / Matrix / DOR for Pricing Responsiblities | G6: Ahmad Yakuba | H6: Allen Douglas | I6: In Review | J6: Use Item 44 final documentation as a go-by and produce the same for Electrical Sent to Allen for review | K6: Medium | M6: =IF(K6="Critical",4,IF(K6="High",3,IF(K6="Medium",2,IF(K6="Low",1,0)))) -> 2 | N6: 0.9 | O6: =IF(N6="",IF(I6="Closed Out",1,IF(I6="Complete",1,IF(I6="Approved",1,IF(I6="Reviewed",1,IF(I6="In Review",0.9,IF(I6="75% Complete",0.75,IF(I6="50% Complete",0.5,IF(I6="25% Complete",0.25,IF(I6="Started",0.25,0))))))))),MAX(IF(I6="Closed Out",1,IF(I6="Complete",1,IF(I6="Approved",1,IF(I6="Reviewed",1,IF(I6="In Review",0.9,IF(I6="75% Complete",0.75,IF(I6="50% Complete",0.5,IF(I6="25% Complete",0.25,IF(I6="Started",0.25,0))))))))),N6)) -> 0.9 | P6: =M6*O6 -> 1.8 | Q6: =IF(OR(I6="Closed Out",I6="Complete",I6="Approved",I6="Reviewed"),"Closed",IF(OR(I6="HOLD",I6="Pause"),"Blocked","Open")) -> Open | R6: =IF(AND(Q6="Open",ISNUMBER(L6),L6<TODAY()),1,0) -> 0 | S6: 0 | V6: =IF(ISNUMBER(L6),"Q"&ROUNDUP(MONTH(L6)/3,0),IF(LEFT(TRIM(CLEAN(L6)),1)="Q","Q"&VALUE(RIGHT(TRIM(CLEAN(L6)),1)),"No Date")) -> No Date
A7: =IF(A6="Item #",1,A6+1) -> 6 | B7: Mock Project Files | C7: E&I Department | D7: Engineering | E7: Standard Template | F7: Pull Rock County Master P&IDs for use on future Mock Projects | G7: Allen Douglas | I7: HOLD | J7: Sabina has stated that PID set is getting scrubbed; ready May 22nd RGLNG is ready for use (PID and Plot Plan) | K7: Low | L7: HOLD | M7: =IF(K7="Critical",4,IF(K7="High",3,IF(K7="Medium",2,IF(K7="Low",1,0)))) -> 1 | N7: 0 | O7: =IF(N7="",IF(I7="Closed Out",1,IF(I7="Complete",1,IF(I7="Approved",1,IF(I7="Reviewed",1,IF(I7="In Review",0.9,IF(I7="75% Complete",0.75,IF(I7="50% Complete",0.5,IF(I7="25% Complete",0.25,IF(I7="Started",0.25,0))))))))),MAX(IF(I7="Closed Out",1,IF(I7="Complete",1,IF(I7="Approved",1,IF(I7="Reviewed",1,IF(I7="In Review",0.9,IF(I7="75% Complete",0.75,IF(I7="50% Complete",0.5,IF(I7="25% Complete",0.25,IF(I7="Started",0.25,0))))))))),N7)) -> 0 | P7: =M7*O7 -> 0 | Q7: =IF(OR(I7="Closed Out",I7="Complete",I7="Approved",I7="Reviewed"),"Closed",IF(OR(I7="HOLD",I7="Pause"),"Blocked","Open")) -> Blocked | R7: =IF(AND(Q7="Open",ISNUMBER(L7),L7<TODAY()),1,0) -> 0 | S7: 0 | V7: =IF(ISNUMBER(L7),"Q"&ROUNDUP(MONTH(L7)/3,0),IF(LEFT(TRIM(CLEAN(L7)),1)="Q","Q"&VALUE(RIGHT(TRIM(CLEAN(L7)),1)),"No Date")) -> No Date
A8: =IF(A7="Item #",1,A7+1) -> 7 | B8: Initiatives - Future | C8: E&I Department | D8: Procurement | E8: Project SharePoint | F8: Update standard folder structure for project and send to Sonya | G8: Ahmad Yakuba | H8: Allen Douglas | I8: Started | J8: Work together through Homer City and submit to DC for implementation | K8: Medium | M8: =IF(K8="Critical",4,IF(K8="High",3,IF(K8="Medium",2,IF(K8="Low",1,0)))) -> 2 | N8: 0.25 | O8: =IF(N8="",IF(I8="Closed Out",1,IF(I8="Complete",1,IF(I8="Approved",1,IF(I8="Reviewed",1,IF(I8="In Review",0.9,IF(I8="75% Complete",0.75,IF(I8="50% Complete",0.5,IF(I8="25% Complete",0.25,IF(I8="Started",0.25,0))))))))),MAX(IF(I8="Closed Out",1,IF(I8="Complete",1,IF(I8="Approved",1,IF(I8="Reviewed",1,IF(I8="In Review",0.9,IF(I8="75% Complete",0.75,IF(I8="50% Complete",0.5,IF(I8="25% Complete",0.25,IF(I8="Started",0.25,0))))))))),N8)) -> 0.25 | P8: =M8*O8 -> 0.5 | Q8: =IF(OR(I8="Closed Out",I8="Complete",I8="Approved",I8="Reviewed"),"Closed",IF(OR(I8="HOLD",I8="Pause"),"Blocked","Open")) -> Open | R8: =IF(AND(Q8="Open",ISNUMBER(L8),L8<TODAY()),1,0) -> 0 | S8: 0 | V8: =IF(ISNUMBER(L8),"Q"&ROUNDUP(MONTH(L8)/3,0),IF(LEFT(TRIM(CLEAN(L8)),1)="Q","Q"&VALUE(RIGHT(TRIM(CLEAN(L8)),1)),"No Date")) -> No Date
A9: =IF(A8="Item #",1,A8+1) -> 8 | B9: Initiatives - Future | C9: E&I Department | D9: Estimating | E9: Historical / Benchmark Improvement IO 101023945 | F9: Ship-Loose database to be used on class2 and indicative estimates quantities, for mechancial equipment. | G9: Ahmed Sherif | I9: HOLD | J9: Starting April 23rd. TO start having contact with Aden and Keshika to finalize the modoule's quantities fillout on Query software. Push to Quarter 3 start to prioritize Energy procedures | K9: Medium | L9: Q3 | M9: =IF(K9="Critical",4,IF(K9="High",3,IF(K9="Medium",2,IF(K9="Low",1,0)))) -> 2 | N9: 0 | O9: =IF(N9="",IF(I9="Closed Out",1,IF(I9="Complete",1,IF(I9="Approved",1,IF(I9="Reviewed",1,IF(I9="In Review",0.9,IF(I9="75% Complete",0.75,IF(I9="50% Complete",0.5,IF(I9="25% Complete",0.25,IF(I9="Started",0.25,0))))))))),MAX(IF(I9="Closed Out",1,IF(I9="Complete",1,IF(I9="Approved",1,IF(I9="Reviewed",1,IF(I9="In Review",0.9,IF(I9="75% Complete",0.75,IF(I9="50% Complete",0.5,IF(I9="25% Complete",0.25,IF(I9="Started",0.25,0))))))))),N9)) -> 0 | P9: =M9*O9 -> 0 | Q9: =IF(OR(I9="Closed Out",I9="Complete",I9="Approved",I9="Reviewed"),"Closed",IF(OR(I9="HOLD",I9="Pause"),"Blocked","Open")) -> Blocked | R9: =IF(AND(Q9="Open",ISNUMBER(L9),L9<TODAY()),1,0) -> 0 | S9: 0 | V9: =IF(ISNUMBER(L9),"Q"&ROUNDUP(MONTH(L9)/3,0),IF(LEFT(TRIM(CLEAN(L9)),1)="Q","Q"&VALUE(RIGHT(TRIM(CLEAN(L9)),1)),"No Date")) -> Q3
A10: =IF(A9="Item #",1,A9+1) -> 9 | B10: Consistency Workshop | C10: OGC | D10: Department | E10: OGC Estimate Checklist | F10: Review and provide feedback to management on current checklist | G10: Allen Douglas | I10: Not Started | K10: Critical | L10: 45789 | M10: =IF(K10="Critical",4,IF(K10="High",3,IF(K10="Medium",2,IF(K10="Low",1,0)))) -> 4 | N10: 0 | O10: =IF(N10="",IF(I10="Closed Out",1,IF(I10="Complete",1,IF(I10="Approved",1,IF(I10="Reviewed",1,IF(I10="In Review",0.9,IF(I10="75% Complete",0.75,IF(I10="50% Complete",0.5,IF(I10="25% Complete",0.25,IF(I10="Started",0.25,0))))))))),MAX(IF(I10="Closed Out",1,IF(I10="Complete",1,IF(I10="Approved",1,IF(I10="Reviewed",1,IF(I10="In Review",0.9,IF(I10="75% Complete",0.75,IF(I10="50% Complete",0.5,IF(I10="25% Complete",0.25,IF(I10="Started",0.25,0))))))))),N10)) -> 0 | P10: =M10*O10 -> 0 | Q10: =IF(OR(I10="Closed Out",I10="Complete",I10="Approved",I10="Reviewed"),"Closed",IF(OR(I10="HOLD",I10="Pause"),"Blocked","Open")) -> Open | R10: =IF(AND(Q10="Open",ISNUMBER(L10),L10<TODAY()),1,0) -> 1 | S10: 0 | V10: =IF(ISNUMBER(L10),"Q"&ROUNDUP(MONTH(L10)/3,0),IF(LEFT(TRIM(CLEAN(L10)),1)="Q","Q"&VALUE(RIGHT(TRIM(CLEAN(L10)),1)),"No Date")) -> Q2
A11: =IF(A10="Item #",1,A10+1) -> 10 | B11: I&C Adapt Logic | C11: Instrumentation and Controls | D11: Estimating | E11: ADAPT - Logic | F11: Re-do logic test to validate changes/corrections by Adapt Team | G11: Keshika Nath Varma | H11: Rene Contreras | I11: Closed Out | J11: Run the test in Adapt for updates completed by Adapt team. Some modifications not done yet by Adapt team. | K11: High | L11: 45795 | M11: =IF(K11="Critical",4,IF(K11="High",3,IF(K11="Medium",2,IF(K11="Low",1,0)))) -> 3 | N11: 1 | O11: =IF(N11="",IF(I11="Closed Out",1,IF(I11="Complete",1,IF(I11="Approved",1,IF(I11="Reviewed",1,IF(I11="In Review",0.9,IF(I11="75% Complete",0.75,IF(I11="50% Complete",0.5,IF(I11="25% Complete",0.25,IF(I11="Started",0.25,0))))))))),MAX(IF(I11="Closed Out",1,IF(I11="Complete",1,IF(I11="Approved",1,IF(I11="Reviewed",1,IF(I11="In Review",0.9,IF(I11="75% Complete",0.75,IF(I11="50% Complete",0.5,IF(I11="25% Complete",0.25,IF(I11="Started",0.25,0))))))))),N11)) -> 1 | P11: =M11*O11 -> 3 | Q11: =IF(OR(I11="Closed Out",I11="Complete",I11="Approved",I11="Reviewed"),"Closed",IF(OR(I11="HOLD",I11="Pause"),"Blocked","Open")) -> Closed | R11: =IF(AND(Q11="Open",ISNUMBER(L11),L11<TODAY()),1,0) -> 0 | S11: 0 | V11: =IF(ISNUMBER(L11),"Q"&ROUNDUP(MONTH(L11)/3,0),IF(LEFT(TRIM(CLEAN(L11)),1)="Q","Q"&VALUE(RIGHT(TRIM(CLEAN(L11)),1)),"No Date")) -> Q2
A12: =IF(A11="Item #",1,A11+1) -> 11 | B12: Department Display | C12: E&I Department | D12: Estimating | E12: Presentation | F12: Build out Technline Racks and Install equipment / Raceways | G12: Andy Baruth | I12: HOLD | J12: Texas LNG | K12: Low | L12: when hell freezes over | M12: =IF(K12="Critical",4,IF(K12="High",3,IF(K12="Medium",2,IF(K12="Low",1,0)))) -> 1 | N12: 0 | O12: =IF(N12="",IF(I12="Closed Out",1,IF(I12="Complete",1,IF(I12="Approved",1,IF(I12="Reviewed",1,IF(I12="In Review",0.9,IF(I12="75% Complete",0.75,IF(I12="50% Complete",0.5,IF(I12="25% Complete",0.25,IF(I12="Started",0.25,0))))))))),MAX(IF(I12="Closed Out",1,IF(I12="Complete",1,IF(I12="Approved",1,IF(I12="Reviewed",1,IF(I12="In Review",0.9,IF(I12="75% Complete",0.75,IF(I12="50% Complete",0.5,IF(I12="25% Complete",0.25,IF(I12="Started",0.25,0))))))))),N12)) -> 0 | P12: =M12*O12 -> 0 | Q12: =IF(OR(I12="Closed Out",I12="Complete",I12="Approved",I12="Reviewed"),"Closed",IF(OR(I12="HOLD",I12="Pause"),"Blocked","Open")) -> Blocked | R12: =IF(AND(Q12="Open",ISNUMBER(L12),L12<TODAY()),1,0) -> 0 | S12: 0 | V12: =IF(ISNUMBER(L12),"Q"&ROUNDUP(MONTH(L12)/3,0),IF(LEFT(TRIM(CLEAN(L12)),1)="Q","Q"&VALUE(RIGHT(TRIM(CLEAN(L12)),1)),"No Date")) -> No Date
A13: =IF(A12="Item #",1,A12+1) -> 12 | B13: White Paper Reports | C13: E&I Department | D13: Estimating | E13: Lessons Learned / White Paper | F13: Manage Procurement Comments | G13: Vendor | I13: HOLD | J13: Due before next week Wholesale Electric meeting | K13: Critical | M13: =IF(K13="Critical",4,IF(K13="High",3,IF(K13="Medium",2,IF(K13="Low",1,0)))) -> 4 | N13: 0 | O13: =IF(N13="",IF(I13="Closed Out",1,IF(I13="Complete",1,IF(I13="Approved",1,IF(I13="Reviewed",1,IF(I13="In Review",0.9,IF(I13="75% Complete",0.75,IF(I13="50% Complete",0.5,IF(I13="25% Complete",0.25,IF(I13="Started",0.25,0))))))))),MAX(IF(I13="Closed Out",1,IF(I13="Complete",1,IF(I13="Approved",1,IF(I13="Reviewed",1,IF(I13="In Review",0.9,IF(I13="75% Complete",0.75,IF(I13="50% Complete",0.5,IF(I13="25% Complete",0.25,IF(I13="Started",0.25,0))))))))),N13)) -> 0 | P13: =M13*O13 -> 0 | Q13: =IF(OR(I13="Closed Out",I13="Complete",I13="Approved",I13="Reviewed"),"Closed",IF(OR(I13="HOLD",I13="Pause"),"Blocked","Open")) -> Blocked | R13: =IF(AND(Q13="Open",ISNUMBER(L13),L13<TODAY()),1,0) -> 0 | S13: 0 | V13: =IF(ISNUMBER(L13),"Q"&ROUNDUP(MONTH(L13)/3,0),IF(LEFT(TRIM(CLEAN(L13)),1)="Q","Q"&VALUE(RIGHT(TRIM(CLEAN(L13)),1)),"No Date")) -> No Date
A14: =IF(A13="Item #",1,A13+1) -> 13 | B14: Consistency Workshop | C14: Instrumentation and Controls | D14: Department | E14: Standard Template | F14: Module Materail Quantity Automation Tool | G14: Ahmed Sherif | I14: 50% Complete | J14: Automate and align BOQ document with ADAPT account codes. Conducted meeting with Ibrahim. Updating BOQ to include necessary details | K14: Low | L14: Q3 | M14: =IF(K14="Critical",4,IF(K14="High",3,IF(K14="Medium",2,IF(K14="Low",1,0)))) -> 1 | N14: 0.5 | O14: =IF(N14="",IF(I14="Closed Out",1,IF(I14="Complete",1,IF(I14="Approved",1,IF(I14="Reviewed",1,IF(I14="In Review",0.9,IF(I14="75% Complete",0.75,IF(I14="50% Complete",0.5,IF(I14="25% Complete",0.25,IF(I14="Started",0.25,0))))))))),MAX(IF(I14="Closed Out",1,IF(I14="Complete",1,IF(I14="Approved",1,IF(I14="Reviewed",1,IF(I14="In Review",0.9,IF(I14="75% Complete",0.75,IF(I14="50% Complete",0.5,IF(I14="25% Complete",0.25,IF(I14="Started",0.25,0))))))))),N14)) -> 0.5 | P14: =M14*O14 -> 0.5 | Q14: =IF(OR(I14="Closed Out",I14="Complete",I14="Approved",I14="Reviewed"),"Closed",IF(OR(I14="HOLD",I14="Pause"),"Blocked","Open")) -> Open | R14: =IF(AND(Q14="Open",ISNUMBER(L14),L14<TODAY()),1,0) -> 0 | S14: 0 | V14: =IF(ISNUMBER(L14),"Q"&ROUNDUP(MONTH(L14)/3,0),IF(LEFT(TRIM(CLEAN(L14)),1)="Q","Q"&VALUE(RIGHT(TRIM(CLEAN(L14)),1)),"No Date")) -> Q3
A15: =IF(A14="Item #",1,A14+1) -> 14 | B15: White Paper Reports | C15: E&I Department | D15: Estimating | E15: Lessons Learned / White Paper | F15: RGLNG White Paper(s) TBD | G15: Construction | I15: HOLD | J15: Allen has emails from Engineering and needs Carlos Serrano at site to give construction lessons learned. Not a push until GTPP Item 11 is complete | K15: Critical | M15: =IF(K15="Critical",4,IF(K15="High",3,IF(K15="Medium",2,IF(K15="Low",1,0)))) -> 4 | N15: 0 | O15: =IF(N15="",IF(I15="Closed Out",1,IF(I15="Complete",1,IF(I15="Approved",1,IF(I15="Reviewed",1,IF(I15="In Review",0.9,IF(I15="75% Complete",0.75,IF(I15="50% Complete",0.5,IF(I15="25% Complete",0.25,IF(I15="Started",0.25,0))))))))),MAX(IF(I15="Closed Out",1,IF(I15="Complete",1,IF(I15="Approved",1,IF(I15="Reviewed",1,IF(I15="In Review",0.9,IF(I15="75% Complete",0.75,IF(I15="50% Complete",0.5,IF(I15="25% Complete",0.25,IF(I15="Started",0.25,0))))))))),N15)) -> 0 | P15: =M15*O15 -> 0 | Q15: =IF(OR(I15="Closed Out",I15="Complete",I15="Approved",I15="Reviewed"),"Closed",IF(OR(I15="HOLD",I15="Pause"),"Blocked","Open")) -> Blocked | R15: =IF(AND(Q15="Open",ISNUMBER(L15),L15<TODAY()),1,0) -> 0 | S15: 0 | V15: =IF(ISNUMBER(L15),"Q"&ROUNDUP(MONTH(L15)/3,0),IF(LEFT(TRIM(CLEAN(L15)),1)="Q","Q"&VALUE(RIGHT(TRIM(CLEAN(L15)),1)),"No Date")) -> No Date
A16: =IF(A15="Item #",1,A15+1) -> 15 | B16: Consistency Workshop | C16: E&I Department | D16: Wire and Cable | E16: Cable List | F16: Update / check termination count for all cables - 1.0 version 3 cable list has issues in termination formulas that have to be fixed | G16: Tyler Reck | H16: Andy Baruth | I16: Approved | J16: 06/15/2026 - 1.) Used "000000-EL-SPC-0005_Wire and Cable Specification" to add all cables to list. 2.) Wrote formula to quantify terminations and grounding. 3.) Need to write formula on main cable schedule sheet to add Armor and Shield terms. 06/16/2026 - 1.) Rewrote layouts for each page, to work with new formulas. 06/17/2026 - 1.) Finished writing new formula for displaying Wire and Cables, Termination, and Gland Pages 06/18/2026 - 1.) Had meeting with Andy and Raul, tested sheet and got sign off. | K16: High | L16: 46190 | M16: =IF(K16="Critical",4,IF(K16="High",3,IF(K16="Medium",2,IF(K16="Low",1,0)))) -> 3 | N16: 1 | O16: =IF(N16="",IF(I16="Closed Out",1,IF(I16="Complete",1,IF(I16="Approved",1,IF(I16="Reviewed",1,IF(I16="In Review",0.9,IF(I16="75% Complete",0.75,IF(I16="50% Complete",0.5,IF(I16="25% Complete",0.25,IF(I16="Started",0.25,0))))))))),MAX(IF(I16="Closed Out",1,IF(I16="Complete",1,IF(I16="Approved",1,IF(I16="Reviewed",1,IF(I16="In Review",0.9,IF(I16="75% Complete",0.75,IF(I16="50% Complete",0.5,IF(I16="25% Complete",0.25,IF(I16="Started",0.25,0))))))))),N16)) -> 1 | P16: =M16*O16 -> 3 | Q16: =IF(OR(I16="Closed Out",I16="Complete",I16="Approved",I16="Reviewed"),"Closed",IF(OR(I16="HOLD",I16="Pause"),"Blocked","Open")) -> Closed | R16: =IF(AND(Q16="Open",ISNUMBER(L16),L16<TODAY()),1,0) -> 0 | S16: 0 | V16: =IF(ISNUMBER(L16),"Q"&ROUNDUP(MONTH(L16)/3,0),IF(LEFT(TRIM(CLEAN(L16)),1)="Q","Q"&VALUE(RIGHT(TRIM(CLEAN(L16)),1)),"No Date")) -> Q2
A17: =IF(A16="Item #",1,A16+1) -> 16 | B17: Consistency Workshop | C17: Electrical | D17: Grounding | E17: ADAPT - Assemblies / KIDs | F17: Report back to department what grounding in ADAPT looks like | G17: Ali Malik | H17: Allen Douglas | I17: 50% Complete | J17: Moves from Oscar to Ali due to Nuclear assigment | K17: High | L17: Q3 | M17: =IF(K17="Critical",4,IF(K17="High",3,IF(K17="Medium",2,IF(K17="Low",1,0)))) -> 3 | N17: 0.5 | O17: =IF(N17="",IF(I17="Closed Out",1,IF(I17="Complete",1,IF(I17="Approved",1,IF(I17="Reviewed",1,IF(I17="In Review",0.9,IF(I17="75% Complete",0.75,IF(I17="50% Complete",0.5,IF(I17="25% Complete",0.25,IF(I17="Started",0.25,0))))))))),MAX(IF(I17="Closed Out",1,IF(I17="Complete",1,IF(I17="Approved",1,IF(I17="Reviewed",1,IF(I17="In Review",0.9,IF(I17="75% Complete",0.75,IF(I17="50% Complete",0.5,IF(I17="25% Complete",0.25,IF(I17="Started",0.25,0))))))))),N17)) -> 0.5 | P17: =M17*O17 -> 1.5 | Q17: =IF(OR(I17="Closed Out",I17="Complete",I17="Approved",I17="Reviewed"),"Closed",IF(OR(I17="HOLD",I17="Pause"),"Blocked","Open")) -> Open | R17: =IF(AND(Q17="Open",ISNUMBER(L17),L17<TODAY()),1,0) -> 0 | S17: 0 | V17: =IF(ISNUMBER(L17),"Q"&ROUNDUP(MONTH(L17)/3,0),IF(LEFT(TRIM(CLEAN(L17)),1)="Q","Q"&VALUE(RIGHT(TRIM(CLEAN(L17)),1)),"No Date")) -> Q3
A18: =IF(A17="Item #",1,A17+1) -> 17 | B18: Initiatives Folder | C18: E&I Department | D18: Department | E18: Standard Template | F18: Create Action Item List for E&I Department Initiative Tracking | G18: Allen Douglas | I18: Closed Out | J18: Email sent to department to review and provide feedback | K18: High | L18: 46141 | M18: =IF(K18="Critical",4,IF(K18="High",3,IF(K18="Medium",2,IF(K18="Low",1,0)))) -> 3 | N18: 1 | O18: =IF(N18="",IF(I18="Closed Out",1,IF(I18="Complete",1,IF(I18="Approved",1,IF(I18="Reviewed",1,IF(I18="In Review",0.9,IF(I18="75% Complete",0.75,IF(I18="50% Complete",0.5,IF(I18="25% Complete",0.25,IF(I18="Started",0.25,0))))))))),MAX(IF(I18="Closed Out",1,IF(I18="Complete",1,IF(I18="Approved",1,IF(I18="Reviewed",1,IF(I18="In Review",0.9,IF(I18="75% Complete",0.75,IF(I18="50% Complete",0.5,IF(I18="25% Complete",0.25,IF(I18="Started",0.25,0))))))))),N18)) -> 1 | P18: =M18*O18 -> 3 | Q18: =IF(OR(I18="Closed Out",I18="Complete",I18="Approved",I18="Reviewed"),"Closed",IF(OR(I18="HOLD",I18="Pause"),"Blocked","Open")) -> Closed | R18: =IF(AND(Q18="Open",ISNUMBER(L18),L18<TODAY()),1,0) -> 0 | S18: 0 | V18: =IF(ISNUMBER(L18),"Q"&ROUNDUP(MONTH(L18)/3,0),IF(LEFT(TRIM(CLEAN(L18)),1)="Q","Q"&VALUE(RIGHT(TRIM(CLEAN(L18)),1)),"No Date")) -> Q2
A19: =IF(A18="Item #",1,A18+1) -> 18 | B19: Energy Standardization | C19: Energy | D19: Estimating | E19: Excel Spreadsheet | F19: Add KPE documents to Energy Tracker | G19: Ali Malik | H19: Allen Douglas | I19: Closed Out | J19: Allen needs help with this task. Easy copy and paste 04/30/2026 - Turned back over to Allen to review | K19: Critical | L19: 46142 | M19: =IF(K19="Critical",4,IF(K19="High",3,IF(K19="Medium",2,IF(K19="Low",1,0)))) -> 4 | N19: 1 | O19: =IF(N19="",IF(I19="Closed Out",1,IF(I19="Complete",1,IF(I19="Approved",1,IF(I19="Reviewed",1,IF(I19="In Review",0.9,IF(I19="75% Complete",0.75,IF(I19="50% Complete",0.5,IF(I19="25% Complete",0.25,IF(I19="Started",0.25,0))))))))),MAX(IF(I19="Closed Out",1,IF(I19="Complete",1,IF(I19="Approved",1,IF(I19="Reviewed",1,IF(I19="In Review",0.9,IF(I19="75% Complete",0.75,IF(I19="50% Complete",0.5,IF(I19="25% Complete",0.25,IF(I19="Started",0.25,0))))))))),N19)) -> 1 | P19: =M19*O19 -> 4 | Q19: =IF(OR(I19="Closed Out",I19="Complete",I19="Approved",I19="Reviewed"),"Closed",IF(OR(I19="HOLD",I19="Pause"),"Blocked","Open")) -> Closed | R19: =IF(AND(Q19="Open",ISNUMBER(L19),L19<TODAY()),1,0) -> 0 | S19: 0 | V19: =IF(ISNUMBER(L19),"Q"&ROUNDUP(MONTH(L19)/3,0),IF(LEFT(TRIM(CLEAN(L19)),1)="Q","Q"&VALUE(RIGHT(TRIM(CLEAN(L19)),1)),"No Date")) -> Q2
A20: =IF(A19="Item #",1,A19+1) -> 19 | B20: Vendor Presentations | C20: E&I Department | D20: Estimating | E20: Presentation | F20: Vendor Visit Presenation - Emerson Ovation DCS | G20: Ahmed Sherif | I20: Closed Out | J20: Presented on 06/22 | K20: Low | L20: 46150 | M20: =IF(K20="Critical",4,IF(K20="High",3,IF(K20="Medium",2,IF(K20="Low",1,0)))) -> 1 | N20: 1 | O20: =IF(N20="",IF(I20="Closed Out",1,IF(I20="Complete",1,IF(I20="Approved",1,IF(I20="Reviewed",1,IF(I20="In Review",0.9,IF(I20="75% Complete",0.75,IF(I20="50% Complete",0.5,IF(I20="25% Complete",0.25,IF(I20="Started",0.25,0))))))))),MAX(IF(I20="Closed Out",1,IF(I20="Complete",1,IF(I20="Approved",1,IF(I20="Reviewed",1,IF(I20="In Review",0.9,IF(I20="75% Complete",0.75,IF(I20="50% Complete",0.5,IF(I20="25% Complete",0.25,IF(I20="Started",0.25,0))))))))),N20)) -> 1 | P20: =M20*O20 -> 1 | Q20: =IF(OR(I20="Closed Out",I20="Complete",I20="Approved",I20="Reviewed"),"Closed",IF(OR(I20="HOLD",I20="Pause"),"Blocked","Open")) -> Closed | R20: =IF(AND(Q20="Open",ISNUMBER(L20),L20<TODAY()),1,0) -> 0 | S20: 0 | V20: =IF(ISNUMBER(L20),"Q"&ROUNDUP(MONTH(L20)/3,0),IF(LEFT(TRIM(CLEAN(L20)),1)="Q","Q"&VALUE(RIGHT(TRIM(CLEAN(L20)),1)),"No Date")) -> Q2
A21: =IF(A20="Item #",1,A20+1) -> 20 | B21: Energy Standardization | C21: Electrical | D21: Grounding | E21: Procedure (Energy) | F21: Identify where KPE and OGC are different in procedures | G21: Oscar Handal | H21: Allen Douglas | I21: Closed Out | J21: Started 4/22 per Workshop Findings 06/23/2026 - Procedure template complete | K21: Critical | L21: 46150 | M21: =IF(K21="Critical",4,IF(K21="High",3,IF(K21="Medium",2,IF(K21="Low",1,0)))) -> 4 | N21: 1 | O21: =IF(N21="",IF(I21="Closed Out",1,IF(I21="Complete",1,IF(I21="Approved",1,IF(I21="Reviewed",1,IF(I21="In Review",0.9,IF(I21="75% Complete",0.75,IF(I21="50% Complete",0.5,IF(I21="25% Complete",0.25,IF(I21="Started",0.25,0))))))))),MAX(IF(I21="Closed Out",1,IF(I21="Complete",1,IF(I21="Approved",1,IF(I21="Reviewed",1,IF(I21="In Review",0.9,IF(I21="75% Complete",0.75,IF(I21="50% Complete",0.5,IF(I21="25% Complete",0.25,IF(I21="Started",0.25,0))))))))),N21)) -> 1 | P21: =M21*O21 -> 4 | Q21: =IF(OR(I21="Closed Out",I21="Complete",I21="Approved",I21="Reviewed"),"Closed",IF(OR(I21="HOLD",I21="Pause"),"Blocked","Open")) -> Closed | R21: =IF(AND(Q21="Open",ISNUMBER(L21),L21<TODAY()),1,0) -> 0 | S21: 0 | V21: =IF(ISNUMBER(L21),"Q"&ROUNDUP(MONTH(L21)/3,0),IF(LEFT(TRIM(CLEAN(L21)),1)="Q","Q"&VALUE(RIGHT(TRIM(CLEAN(L21)),1)),"No Date")) -> Q2
A22: =IF(A21="Item #",1,A21+1) -> 21 | B22: Energy Standardization | C22: Electrical | D22: Cable - General | E22: Procedure (Energy) | F22: Identify where KPE and OGC are different in procedures | G22: Tyler Reck | H22: Allen Douglas | I22: Not Started | K22: Critical | L22: 46199 | M22: =IF(K22="Critical",4,IF(K22="High",3,IF(K22="Medium",2,IF(K22="Low",1,0)))) -> 4 | N22: 0 | O22: =IF(N22="",IF(I22="Closed Out",1,IF(I22="Complete",1,IF(I22="Approved",1,IF(I22="Reviewed",1,IF(I22="In Review",0.9,IF(I22="75% Complete",0.75,IF(I22="50% Complete",0.5,IF(I22="25% Complete",0.25,IF(I22="Started",0.25,0))))))))),MAX(IF(I22="Closed Out",1,IF(I22="Complete",1,IF(I22="Approved",1,IF(I22="Reviewed",1,IF(I22="In Review",0.9,IF(I22="75% Complete",0.75,IF(I22="50% Complete",0.5,IF(I22="25% Complete",0.25,IF(I22="Started",0.25,0))))))))),N22)) -> 0 | P22: =M22*O22 -> 0 | Q22: =IF(OR(I22="Closed Out",I22="Complete",I22="Approved",I22="Reviewed"),"Closed",IF(OR(I22="HOLD",I22="Pause"),"Blocked","Open")) -> Open | R22: =IF(AND(Q22="Open",ISNUMBER(L22),L22<TODAY()),1,0) -> 1 | S22: 0 | V22: =IF(ISNUMBER(L22),"Q"&ROUNDUP(MONTH(L22)/3,0),IF(LEFT(TRIM(CLEAN(L22)),1)="Q","Q"&VALUE(RIGHT(TRIM(CLEAN(L22)),1)),"No Date")) -> Q2
A23: =IF(A22="Item #",1,A22+1) -> 22 | B23: Energy Standardization | C23: Electrical | D23: Raceway | E23: Procedure (Energy) | F23: Identify where KPE and OGC are different in procedures | G23: Oscar Handal | H23: Allen Douglas | I23: Closed Out | J23: 06/23/2026 - Procedure template complete | K23: Critical | L23: 46199 | M23: =IF(K23="Critical",4,IF(K23="High",3,IF(K23="Medium",2,IF(K23="Low",1,0)))) -> 4 | N23: 1 | O23: =IF(N23="",IF(I23="Closed Out",1,IF(I23="Complete",1,IF(I23="Approved",1,IF(I23="Reviewed",1,IF(I23="In Review",0.9,IF(I23="75% Complete",0.75,IF(I23="50% Complete",0.5,IF(I23="25% Complete",0.25,IF(I23="Started",0.25,0))))))))),MAX(IF(I23="Closed Out",1,IF(I23="Complete",1,IF(I23="Approved",1,IF(I23="Reviewed",1,IF(I23="In Review",0.9,IF(I23="75% Complete",0.75,IF(I23="50% Complete",0.5,IF(I23="25% Complete",0.25,IF(I23="Started",0.25,0))))))))),N23)) -> 1 | P23: =M23*O23 -> 4 | Q23: =IF(OR(I23="Closed Out",I23="Complete",I23="Approved",I23="Reviewed"),"Closed",IF(OR(I23="HOLD",I23="Pause"),"Blocked","Open")) -> Closed | R23: =IF(AND(Q23="Open",ISNUMBER(L23),L23<TODAY()),1,0) -> 0 | S23: 0 | V23: =IF(ISNUMBER(L23),"Q"&ROUNDUP(MONTH(L23)/3,0),IF(LEFT(TRIM(CLEAN(L23)),1)="Q","Q"&VALUE(RIGHT(TRIM(CLEAN(L23)),1)),"No Date")) -> Q2
A24: =IF(A23="Item #",1,A23+1) -> 23 | B24: Energy Standardization | C24: Electrical | D24: Lighting | E24: Procedure (Energy) | F24: Identify where KPE and OGC are different in procedures | G24: Rojna Ghamsari | H24: Allen Douglas | I24: Closed Out | K24: Critical | L24: 46199 | M24: =IF(K24="Critical",4,IF(K24="High",3,IF(K24="Medium",2,IF(K24="Low",1,0)))) -> 4 | N24: 1 | O24: =IF(N24="",IF(I24="Closed Out",1,IF(I24="Complete",1,IF(I24="Approved",1,IF(I24="Reviewed",1,IF(I24="In Review",0.9,IF(I24="75% Complete",0.75,IF(I24="50% Complete",0.5,IF(I24="25% Complete",0.25,IF(I24="Started",0.25,0))))))))),MAX(IF(I24="Closed Out",1,IF(I24="Complete",1,IF(I24="Approved",1,IF(I24="Reviewed",1,IF(I24="In Review",0.9,IF(I24="75% Complete",0.75,IF(I24="50% Complete",0.5,IF(I24="25% Complete",0.25,IF(I24="Started",0.25,0))))))))),N24)) -> 1 | P24: =M24*O24 -> 4 | Q24: =IF(OR(I24="Closed Out",I24="Complete",I24="Approved",I24="Reviewed"),"Closed",IF(OR(I24="HOLD",I24="Pause"),"Blocked","Open")) -> Closed | R24: =IF(AND(Q24="Open",ISNUMBER(L24),L24<TODAY()),1,0) -> 0 | S24: 0 | V24: =IF(ISNUMBER(L24),"Q"&ROUNDUP(MONTH(L24)/3,0),IF(LEFT(TRIM(CLEAN(L24)),1)="Q","Q"&VALUE(RIGHT(TRIM(CLEAN(L24)),1)),"No Date")) -> Q2
A25: =IF(A21="Item #",1,A21+1) -> 21 | B25: Energy Standardization | C25: Electrical | D25: Heat Trace | E25: Procedure (Energy) | F25: Identify where KPE and OGC are different in procedures | G25: Syed Ali | H25: Allen Douglas | I25: Closed Out | J25: 06/24/2026 - Procedure template complete | K25: Critical | L25: 46199 | M25: =IF(K25="Critical",4,IF(K25="High",3,IF(K25="Medium",2,IF(K25="Low",1,0)))) -> 4 | N25: 1 | O25: =IF(N25="",IF(I25="Closed Out",1,IF(I25="Complete",1,IF(I25="Approved",1,IF(I25="Reviewed",1,IF(I25="In Review",0.9,IF(I25="75% Complete",0.75,IF(I25="50% Complete",0.5,IF(I25="25% Complete",0.25,IF(I25="Started",0.25,0))))))))),MAX(IF(I25="Closed Out",1,IF(I25="Complete",1,IF(I25="Approved",1,IF(I25="Reviewed",1,IF(I25="In Review",0.9,IF(I25="75% Complete",0.75,IF(I25="50% Complete",0.5,IF(I25="25% Complete",0.25,IF(I25="Started",0.25,0))))))))),N25)) -> 1 | P25: =M25*O25 -> 4 | Q25: =IF(OR(I25="Closed Out",I25="Complete",I25="Approved",I25="Reviewed"),"Closed",IF(OR(I25="HOLD",I25="Pause"),"Blocked","Open")) -> Closed | R25: =IF(AND(Q25="Open",ISNUMBER(L25),L25<TODAY()),1,0) -> 0 | S25: 0 | V25: =IF(ISNUMBER(L25),"Q"&ROUNDUP(MONTH(L25)/3,0),IF(LEFT(TRIM(CLEAN(L25)),1)="Q","Q"&VALUE(RIGHT(TRIM(CLEAN(L25)),1)),"No Date")) -> Q2
A26: =IF(A25="Item #",1,A25+1) -> 22 | B26: Energy Standardization | C26: Electrical | D26: Lightning Protection | E26: Procedure (Energy) | F26: Identify where KPE and OGC are different in procedures | G26: Ahmad Yakuba | H26: Allen Douglas | I26: Not Started | K26: Critical | L26: 46199 | M26: =IF(K26="Critical",4,IF(K26="High",3,IF(K26="Medium",2,IF(K26="Low",1,0)))) -> 4 | N26: 0 | O26: =IF(N26="",IF(I26="Closed Out",1,IF(I26="Complete",1,IF(I26="Approved",1,IF(I26="Reviewed",1,IF(I26="In Review",0.9,IF(I26="75% Complete",0.75,IF(I26="50% Complete",0.5,IF(I26="25% Complete",0.25,IF(I26="Started",0.25,0))))))))),MAX(IF(I26="Closed Out",1,IF(I26="Complete",1,IF(I26="Approved",1,IF(I26="Reviewed",1,IF(I26="In Review",0.9,IF(I26="75% Complete",0.75,IF(I26="50% Complete",0.5,IF(I26="25% Complete",0.25,IF(I26="Started",0.25,0))))))))),N26)) -> 0 | P26: =M26*O26 -> 0 | Q26: =IF(OR(I26="Closed Out",I26="Complete",I26="Approved",I26="Reviewed"),"Closed",IF(OR(I26="HOLD",I26="Pause"),"Blocked","Open")) -> Open | R26: =IF(AND(Q26="Open",ISNUMBER(L26),L26<TODAY()),1,0) -> 1 | S26: 0 | V26: =IF(ISNUMBER(L26),"Q"&ROUNDUP(MONTH(L26)/3,0),IF(LEFT(TRIM(CLEAN(L26)),1)="Q","Q"&VALUE(RIGHT(TRIM(CLEAN(L26)),1)),"No Date")) -> Q2
A27: =IF(A26="Item #",1,A26+1) -> 23 | B27: Energy Standardization | C27: Electrical | D27: Cathodic Protection | E27: Procedure (Energy) | F27: Identify where KPE and OGC are different in procedures | G27: Ahmad Yakuba | H27: Allen Douglas | I27: Not Started | K27: Critical | L27: 46199 | M27: =IF(K27="Critical",4,IF(K27="High",3,IF(K27="Medium",2,IF(K27="Low",1,0)))) -> 4 | N27: 0 | O27: =IF(N27="",IF(I27="Closed Out",1,IF(I27="Complete",1,IF(I27="Approved",1,IF(I27="Reviewed",1,IF(I27="In Review",0.9,IF(I27="75% Complete",0.75,IF(I27="50% Complete",0.5,IF(I27="25% Complete",0.25,IF(I27="Started",0.25,0))))))))),MAX(IF(I27="Closed Out",1,IF(I27="Complete",1,IF(I27="Approved",1,IF(I27="Reviewed",1,IF(I27="In Review",0.9,IF(I27="75% Complete",0.75,IF(I27="50% Complete",0.5,IF(I27="25% Complete",0.25,IF(I27="Started",0.25,0))))))))),N27)) -> 0 | P27: =M27*O27 -> 0 | Q27: =IF(OR(I27="Closed Out",I27="Complete",I27="Approved",I27="Reviewed"),"Closed",IF(OR(I27="HOLD",I27="Pause"),"Blocked","Open")) -> Open | R27: =IF(AND(Q27="Open",ISNUMBER(L27),L27<TODAY()),1,0) -> 1 | S27: 0 | V27: =IF(ISNUMBER(L27),"Q"&ROUNDUP(MONTH(L27)/3,0),IF(LEFT(TRIM(CLEAN(L27)),1)="Q","Q"&VALUE(RIGHT(TRIM(CLEAN(L27)),1)),"No Date")) -> Q2
A28: =IF(A27="Item #",1,A27+1) -> 24 | B28: Energy Standardization | C28: Electrical | D28: Temporary Power | E28: Procedure (Energy) | F28: Identify where KPE and OGC are different in procedures | G28: Syed Ali | H28: Allen Douglas | I28: Closed Out | J28: 06/24/2026 - Procedure template complete | K28: Critical | L28: 46199 | M28: =IF(K28="Critical",4,IF(K28="High",3,IF(K28="Medium",2,IF(K28="Low",1,0)))) -> 4 | N28: 1 | O28: =IF(N28="",IF(I28="Closed Out",1,IF(I28="Complete",1,IF(I28="Approved",1,IF(I28="Reviewed",1,IF(I28="In Review",0.9,IF(I28="75% Complete",0.75,IF(I28="50% Complete",0.5,IF(I28="25% Complete",0.25,IF(I28="Started",0.25,0))))))))),MAX(IF(I28="Closed Out",1,IF(I28="Complete",1,IF(I28="Approved",1,IF(I28="Reviewed",1,IF(I28="In Review",0.9,IF(I28="75% Complete",0.75,IF(I28="50% Complete",0.5,IF(I28="25% Complete",0.25,IF(I28="Started",0.25,0))))))))),N28)) -> 1 | P28: =M28*O28 -> 4 | Q28: =IF(OR(I28="Closed Out",I28="Complete",I28="Approved",I28="Reviewed"),"Closed",IF(OR(I28="HOLD",I28="Pause"),"Blocked","Open")) -> Closed | R28: =IF(AND(Q28="Open",ISNUMBER(L28),L28<TODAY()),1,0) -> 0 | S28: 0 | V28: =IF(ISNUMBER(L28),"Q"&ROUNDUP(MONTH(L28)/3,0),IF(LEFT(TRIM(CLEAN(L28)),1)="Q","Q"&VALUE(RIGHT(TRIM(CLEAN(L28)),1)),"No Date")) -> Q2
A29: =IF(A28="Item #",1,A28+1) -> 25 | B29: Energy Standardization | C29: Electrical | D29: Fire Safety System | E29: Procedure (Energy) | F29: Identify where KPE and OGC are different in procedures | G29: Keshika Nath Varma | H29: Allen Douglas | I29: Closed Out | K29: Critical | L29: 46199 | M29: =IF(K29="Critical",4,IF(K29="High",3,IF(K29="Medium",2,IF(K29="Low",1,0)))) -> 4 | N29: 1 | O29: =IF(N29="",IF(I29="Closed Out",1,IF(I29="Complete",1,IF(I29="Approved",1,IF(I29="Reviewed",1,IF(I29="In Review",0.9,IF(I29="75% Complete",0.75,IF(I29="50% Complete",0.5,IF(I29="25% Complete",0.25,IF(I29="Started",0.25,0))))))))),MAX(IF(I29="Closed Out",1,IF(I29="Complete",1,IF(I29="Approved",1,IF(I29="Reviewed",1,IF(I29="In Review",0.9,IF(I29="75% Complete",0.75,IF(I29="50% Complete",0.5,IF(I29="25% Complete",0.25,IF(I29="Started",0.25,0))))))))),N29)) -> 1 | P29: =M29*O29 -> 4 | Q29: =IF(OR(I29="Closed Out",I29="Complete",I29="Approved",I29="Reviewed"),"Closed",IF(OR(I29="HOLD",I29="Pause"),"Blocked","Open")) -> Closed | R29: =IF(AND(Q29="Open",ISNUMBER(L29),L29<TODAY()),1,0) -> 0 | S29: 0 | V29: =IF(ISNUMBER(L29),"Q"&ROUNDUP(MONTH(L29)/3,0),IF(LEFT(TRIM(CLEAN(L29)),1)="Q","Q"&VALUE(RIGHT(TRIM(CLEAN(L29)),1)),"No Date")) -> Q2
A30: =IF(A21="Item #",1,A21+1) -> 21 | B30: Energy Standardization | C30: Electrical | D30: Instrumentation | E30: Procedure (Energy) | F30: Identify where KPE and OGC are different in procedures | G30: Keshika Nath Varma | H30: Allen Douglas | I30: Closed Out | K30: Critical | L30: 46199 | M30: =IF(K30="Critical",4,IF(K30="High",3,IF(K30="Medium",2,IF(K30="Low",1,0)))) -> 4 | N30: 1 | O30: =IF(N30="",IF(I30="Closed Out",1,IF(I30="Complete",1,IF(I30="Approved",1,IF(I30="Reviewed",1,IF(I30="In Review",0.9,IF(I30="75% Complete",0.75,IF(I30="50% Complete",0.5,IF(I30="25% Complete",0.25,IF(I30="Started",0.25,0))))))))),MAX(IF(I30="Closed Out",1,IF(I30="Complete",1,IF(I30="Approved",1,IF(I30="Reviewed",1,IF(I30="In Review",0.9,IF(I30="75% Complete",0.75,IF(I30="50% Complete",0.5,IF(I30="25% Complete",0.25,IF(I30="Started",0.25,0))))))))),N30)) -> 1 | P30: =M30*O30 -> 4 | Q30: =IF(OR(I30="Closed Out",I30="Complete",I30="Approved",I30="Reviewed"),"Closed",IF(OR(I30="HOLD",I30="Pause"),"Blocked","Open")) -> Closed | R30: =IF(AND(Q30="Open",ISNUMBER(L30),L30<TODAY()),1,0) -> 0 | S30: 0 | V30: =IF(ISNUMBER(L30),"Q"&ROUNDUP(MONTH(L30)/3,0),IF(LEFT(TRIM(CLEAN(L30)),1)="Q","Q"&VALUE(RIGHT(TRIM(CLEAN(L30)),1)),"No Date")) -> Q2
A31: =IF(A30="Item #",1,A30+1) -> 22 | B31: Energy Standardization | C31: Electrical | D31: Control Systems | E31: Procedure (Energy) | F31: Identify where KPE and OGC are different in procedures | G31: Ahmed Sherif | H31: Allen Douglas | I31: Closed Out | K31: Critical | L31: 46199 | M31: =IF(K31="Critical",4,IF(K31="High",3,IF(K31="Medium",2,IF(K31="Low",1,0)))) -> 4 | N31: 1 | O31: =IF(N31="",IF(I31="Closed Out",1,IF(I31="Complete",1,IF(I31="Approved",1,IF(I31="Reviewed",1,IF(I31="In Review",0.9,IF(I31="75% Complete",0.75,IF(I31="50% Complete",0.5,IF(I31="25% Complete",0.25,IF(I31="Started",0.25,0))))))))),MAX(IF(I31="Closed Out",1,IF(I31="Complete",1,IF(I31="Approved",1,IF(I31="Reviewed",1,IF(I31="In Review",0.9,IF(I31="75% Complete",0.75,IF(I31="50% Complete",0.5,IF(I31="25% Complete",0.25,IF(I31="Started",0.25,0))))))))),N31)) -> 1 | P31: =M31*O31 -> 4 | Q31: =IF(OR(I31="Closed Out",I31="Complete",I31="Approved",I31="Reviewed"),"Closed",IF(OR(I31="HOLD",I31="Pause"),"Blocked","Open")) -> Closed | R31: =IF(AND(Q31="Open",ISNUMBER(L31),L31<TODAY()),1,0) -> 0 | S31: 0 | V31: =IF(ISNUMBER(L31),"Q"&ROUNDUP(MONTH(L31)/3,0),IF(LEFT(TRIM(CLEAN(L31)),1)="Q","Q"&VALUE(RIGHT(TRIM(CLEAN(L31)),1)),"No Date")) -> Q2
A32: =IF(A31="Item #",1,A31+1) -> 23 | B32: Energy Standardization | C32: Electrical | D32: Telecoms | E32: Procedure (Energy) | F32: Identify where KPE and OGC are different in procedures | G32: Rasheed Oduro | H32: Allen Douglas | I32: Closed Out | J32: 06/22/2026 - Procedure template complete | K32: Critical | L32: 46150 | M32: =IF(K32="Critical",4,IF(K32="High",3,IF(K32="Medium",2,IF(K32="Low",1,0)))) -> 4 | N32: 1 | O32: =IF(N32="",IF(I32="Closed Out",1,IF(I32="Complete",1,IF(I32="Approved",1,IF(I32="Reviewed",1,IF(I32="In Review",0.9,IF(I32="75% Complete",0.75,IF(I32="50% Complete",0.5,IF(I32="25% Complete",0.25,IF(I32="Started",0.25,0))))))))),MAX(IF(I32="Closed Out",1,IF(I32="Complete",1,IF(I32="Approved",1,IF(I32="Reviewed",1,IF(I32="In Review",0.9,IF(I32="75% Complete",0.75,IF(I32="50% Complete",0.5,IF(I32="25% Complete",0.25,IF(I32="Started",0.25,0))))))))),N32)) -> 1 | P32: =M32*O32 -> 4 | Q32: =IF(OR(I32="Closed Out",I32="Complete",I32="Approved",I32="Reviewed"),"Closed",IF(OR(I32="HOLD",I32="Pause"),"Blocked","Open")) -> Closed | R32: =IF(AND(Q32="Open",ISNUMBER(L32),L32<TODAY()),1,0) -> 0 | S32: 0 | V32: =IF(ISNUMBER(L32),"Q"&ROUNDUP(MONTH(L32)/3,0),IF(LEFT(TRIM(CLEAN(L32)),1)="Q","Q"&VALUE(RIGHT(TRIM(CLEAN(L32)),1)),"No Date")) -> Q2
A33: =IF(A32="Item #",1,A32+1) -> 24 | B33: Energy Standardization | C33: Electrical | D33: Security | E33: Procedure (Energy) | F33: Identify where KPE and OGC are different in procedures | G33: Rasheed Oduro | H33: Allen Douglas | I33: Closed Out | J33: 06/22/2026 - Procedure template complete | K33: Critical | L33: 46150 | M33: =IF(K33="Critical",4,IF(K33="High",3,IF(K33="Medium",2,IF(K33="Low",1,0)))) -> 4 | N33: 1 | O33: =IF(N33="",IF(I33="Closed Out",1,IF(I33="Complete",1,IF(I33="Approved",1,IF(I33="Reviewed",1,IF(I33="In Review",0.9,IF(I33="75% Complete",0.75,IF(I33="50% Complete",0.5,IF(I33="25% Complete",0.25,IF(I33="Started",0.25,0))))))))),MAX(IF(I33="Closed Out",1,IF(I33="Complete",1,IF(I33="Approved",1,IF(I33="Reviewed",1,IF(I33="In Review",0.9,IF(I33="75% Complete",0.75,IF(I33="50% Complete",0.5,IF(I33="25% Complete",0.25,IF(I33="Started",0.25,0))))))))),N33)) -> 1 | P33: =M33*O33 -> 4 | Q33: =IF(OR(I33="Closed Out",I33="Complete",I33="Approved",I33="Reviewed"),"Closed",IF(OR(I33="HOLD",I33="Pause"),"Blocked","Open")) -> Closed | R33: =IF(AND(Q33="Open",ISNUMBER(L33),L33<TODAY()),1,0) -> 0 | S33: 0 | V33: =IF(ISNUMBER(L33),"Q"&ROUNDUP(MONTH(L33)/3,0),IF(LEFT(TRIM(CLEAN(L33)),1)="Q","Q"&VALUE(RIGHT(TRIM(CLEAN(L33)),1)),"No Date")) -> Q2
A34: =IF(A33="Item #",1,A33+1) -> 25 | B34: Energy Standardization | C34: Electrical | D34: Facility Equipment | E34: Procedure (Energy) | F34: Created template procedure for equipment & devices takeoff | G34: Dilan Centeno | H34: Ali Malik | I34: Not Started | K34: Critical | L34: Q2 | M34: =IF(K34="Critical",4,IF(K34="High",3,IF(K34="Medium",2,IF(K34="Low",1,0)))) -> 4 | N34: 0 | O34: =IF(N34="",IF(I34="Closed Out",1,IF(I34="Complete",1,IF(I34="Approved",1,IF(I34="Reviewed",1,IF(I34="In Review",0.9,IF(I34="75% Complete",0.75,IF(I34="50% Complete",0.5,IF(I34="25% Complete",0.25,IF(I34="Started",0.25,0))))))))),MAX(IF(I34="Closed Out",1,IF(I34="Complete",1,IF(I34="Approved",1,IF(I34="Reviewed",1,IF(I34="In Review",0.9,IF(I34="75% Complete",0.75,IF(I34="50% Complete",0.5,IF(I34="25% Complete",0.25,IF(I34="Started",0.25,0))))))))),N34)) -> 0 | P34: =M34*O34 -> 0 | Q34: =IF(OR(I34="Closed Out",I34="Complete",I34="Approved",I34="Reviewed"),"Closed",IF(OR(I34="HOLD",I34="Pause"),"Blocked","Open")) -> Open | R34: =IF(AND(Q34="Open",ISNUMBER(L34),L34<TODAY()),1,0) -> 0 | S34: 0 | V34: =IF(ISNUMBER(L34),"Q"&ROUNDUP(MONTH(L34)/3,0),IF(LEFT(TRIM(CLEAN(L34)),1)="Q","Q"&VALUE(RIGHT(TRIM(CLEAN(L34)),1)),"No Date")) -> Q2
A35: =IF(A21="Item #",1,A21+1) -> 21 | B35: Energy Standardization | C35: Electrical | D35: Equipment and Devices | E35: Procedure (Energy) | F35: Created template procedure for equipment & devices takeoff | G35: Dilan Centeno | H35: Ali Malik | I35: Closed Out | J35: Procedure template reviewed and completed (6/26) | K35: Critical | L35: Q2 | M35: =IF(K35="Critical",4,IF(K35="High",3,IF(K35="Medium",2,IF(K35="Low",1,0)))) -> 4 | N35: 1 | O35: =IF(N35="",IF(I35="Closed Out",1,IF(I35="Complete",1,IF(I35="Approved",1,IF(I35="Reviewed",1,IF(I35="In Review",0.9,IF(I35="75% Complete",0.75,IF(I35="50% Complete",0.5,IF(I35="25% Complete",0.25,IF(I35="Started",0.25,0))))))))),MAX(IF(I35="Closed Out",1,IF(I35="Complete",1,IF(I35="Approved",1,IF(I35="Reviewed",1,IF(I35="In Review",0.9,IF(I35="75% Complete",0.75,IF(I35="50% Complete",0.5,IF(I35="25% Complete",0.25,IF(I35="Started",0.25,0))))))))),N35)) -> 1 | P35: =M35*O35 -> 4 | Q35: =IF(OR(I35="Closed Out",I35="Complete",I35="Approved",I35="Reviewed"),"Closed",IF(OR(I35="HOLD",I35="Pause"),"Blocked","Open")) -> Closed | R35: =IF(AND(Q35="Open",ISNUMBER(L35),L35<TODAY()),1,0) -> 0 | S35: 0 | V35: =IF(ISNUMBER(L35),"Q"&ROUNDUP(MONTH(L35)/3,0),IF(LEFT(TRIM(CLEAN(L35)),1)="Q","Q"&VALUE(RIGHT(TRIM(CLEAN(L35)),1)),"No Date")) -> Q2
A36: =IF(A21="Item #",1,A21+1) -> 21 | B36: Consistency Workshop | C36: Electrical | D36: Lighting | E36: ADAPT - Assemblies / KIDs | F36: Align ADAPT with KOE Installation Details (follow Grounding method) | G36: Oscar Handal | H36: Allen Douglas | I36: 25% Complete | J36: Requires the completion of Grounding as a go-by 06/25/2026 - Started Task parallel to grounding | K36: High | L36: Q3 | M36: =IF(K36="Critical",4,IF(K36="High",3,IF(K36="Medium",2,IF(K36="Low",1,0)))) -> 3 | N36: 0.3 | O36: =IF(N36="",IF(I36="Closed Out",1,IF(I36="Complete",1,IF(I36="Approved",1,IF(I36="Reviewed",1,IF(I36="In Review",0.9,IF(I36="75% Complete",0.75,IF(I36="50% Complete",0.5,IF(I36="25% Complete",0.25,IF(I36="Started",0.25,0))))))))),MAX(IF(I36="Closed Out",1,IF(I36="Complete",1,IF(I36="Approved",1,IF(I36="Reviewed",1,IF(I36="In Review",0.9,IF(I36="75% Complete",0.75,IF(I36="50% Complete",0.5,IF(I36="25% Complete",0.25,IF(I36="Started",0.25,0))))))))),N36)) -> 0.3 | P36: =M36*O36 -> 0.9 | Q36: =IF(OR(I36="Closed Out",I36="Complete",I36="Approved",I36="Reviewed"),"Closed",IF(OR(I36="HOLD",I36="Pause"),"Blocked","Open")) -> Open | R36: =IF(AND(Q36="Open",ISNUMBER(L36),L36<TODAY()),1,0) -> 0 | S36: 0 | V36: =IF(ISNUMBER(L36),"Q"&ROUNDUP(MONTH(L36)/3,0),IF(LEFT(TRIM(CLEAN(L36)),1)="Q","Q"&VALUE(RIGHT(TRIM(CLEAN(L36)),1)),"No Date")) -> Q3
A37: =IF(A36="Item #",1,A36+1) -> 22 | B37: Consistency Workshop | C37: Electrical | D37: Cable Tray | E37: ADAPT - Assemblies / KIDs | F37: Align ADAPT with KOE Installation Details (follow Grounding method) | G37: Available | I37: HOLD | J37: Requires the completion of Grounding as a go-by | K37: High | M37: =IF(K37="Critical",4,IF(K37="High",3,IF(K37="Medium",2,IF(K37="Low",1,0)))) -> 3 | N37: 0 | O37: =IF(N37="",IF(I37="Closed Out",1,IF(I37="Complete",1,IF(I37="Approved",1,IF(I37="Reviewed",1,IF(I37="In Review",0.9,IF(I37="75% Complete",0.75,IF(I37="50% Complete",0.5,IF(I37="25% Complete",0.25,IF(I37="Started",0.25,0))))))))),MAX(IF(I37="Closed Out",1,IF(I37="Complete",1,IF(I37="Approved",1,IF(I37="Reviewed",1,IF(I37="In Review",0.9,IF(I37="75% Complete",0.75,IF(I37="50% Complete",0.5,IF(I37="25% Complete",0.25,IF(I37="Started",0.25,0))))))))),N37)) -> 0 | P37: =M37*O37 -> 0 | Q37: =IF(OR(I37="Closed Out",I37="Complete",I37="Approved",I37="Reviewed"),"Closed",IF(OR(I37="HOLD",I37="Pause"),"Blocked","Open")) -> Blocked | R37: =IF(AND(Q37="Open",ISNUMBER(L37),L37<TODAY()),1,0) -> 0 | S37: 0 | V37: =IF(ISNUMBER(L37),"Q"&ROUNDUP(MONTH(L37)/3,0),IF(LEFT(TRIM(CLEAN(L37)),1)="Q","Q"&VALUE(RIGHT(TRIM(CLEAN(L37)),1)),"No Date")) -> No Date
A38: =IF(A37="Item #",1,A37+1) -> 23 | B38: Consistency Workshop | C38: Electrical | D38: Conduit | E38: ADAPT - Assemblies / KIDs | F38: Align ADAPT with KOE Installation Details (follow Grounding method) | G38: Available | I38: HOLD | J38: Requires the completion of Grounding as a go-by | K38: High | M38: =IF(K38="Critical",4,IF(K38="High",3,IF(K38="Medium",2,IF(K38="Low",1,0)))) -> 3 | N38: 0 | O38: =IF(N38="",IF(I38="Closed Out",1,IF(I38="Complete",1,IF(I38="Approved",1,IF(I38="Reviewed",1,IF(I38="In Review",0.9,IF(I38="75% Complete",0.75,IF(I38="50% Complete",0.5,IF(I38="25% Complete",0.25,IF(I38="Started",0.25,0))))))))),MAX(IF(I38="Closed Out",1,IF(I38="Complete",1,IF(I38="Approved",1,IF(I38="Reviewed",1,IF(I38="In Review",0.9,IF(I38="75% Complete",0.75,IF(I38="50% Complete",0.5,IF(I38="25% Complete",0.25,IF(I38="Started",0.25,0))))))))),N38)) -> 0 | P38: =M38*O38 -> 0 | Q38: =IF(OR(I38="Closed Out",I38="Complete",I38="Approved",I38="Reviewed"),"Closed",IF(OR(I38="HOLD",I38="Pause"),"Blocked","Open")) -> Blocked | R38: =IF(AND(Q38="Open",ISNUMBER(L38),L38<TODAY()),1,0) -> 0 | S38: 0 | V38: =IF(ISNUMBER(L38),"Q"&ROUNDUP(MONTH(L38)/3,0),IF(LEFT(TRIM(CLEAN(L38)),1)="Q","Q"&VALUE(RIGHT(TRIM(CLEAN(L38)),1)),"No Date")) -> No Date
A39: =IF(A38="Item #",1,A38+1) -> 24 | B39: Consistency Workshop | C39: Electrical | D39: Channel Tray | E39: ADAPT - Assemblies / KIDs | F39: Align ADAPT with KOE Installation Details (follow Grounding method) | G39: Available | I39: HOLD | J39: Requires the completion of Grounding as a go-by | K39: High | M39: =IF(K39="Critical",4,IF(K39="High",3,IF(K39="Medium",2,IF(K39="Low",1,0)))) -> 3 | N39: 0 | O39: =IF(N39="",IF(I39="Closed Out",1,IF(I39="Complete",1,IF(I39="Approved",1,IF(I39="Reviewed",1,IF(I39="In Review",0.9,IF(I39="75% Complete",0.75,IF(I39="50% Complete",0.5,IF(I39="25% Complete",0.25,IF(I39="Started",0.25,0))))))))),MAX(IF(I39="Closed Out",1,IF(I39="Complete",1,IF(I39="Approved",1,IF(I39="Reviewed",1,IF(I39="In Review",0.9,IF(I39="75% Complete",0.75,IF(I39="50% Complete",0.5,IF(I39="25% Complete",0.25,IF(I39="Started",0.25,0))))))))),N39)) -> 0 | P39: =M39*O39 -> 0 | Q39: =IF(OR(I39="Closed Out",I39="Complete",I39="Approved",I39="Reviewed"),"Closed",IF(OR(I39="HOLD",I39="Pause"),"Blocked","Open")) -> Blocked | R39: =IF(AND(Q39="Open",ISNUMBER(L39),L39<TODAY()),1,0) -> 0 | S39: 0 | V39: =IF(ISNUMBER(L39),"Q"&ROUNDUP(MONTH(L39)/3,0),IF(LEFT(TRIM(CLEAN(L39)),1)="Q","Q"&VALUE(RIGHT(TRIM(CLEAN(L39)),1)),"No Date")) -> No Date
A40: =IF(A39="Item #",1,A39+1) -> 25 | B40: Consistency Workshop | C40: Electrical | D40: DuctBank | E40: ADAPT - Assemblies / KIDs | F40: Align ADAPT with KOE Installation Details (follow Grounding method) | G40: Available | I40: HOLD | J40: Requires the completion of Grounding as a go-by | K40: High | M40: =IF(K40="Critical",4,IF(K40="High",3,IF(K40="Medium",2,IF(K40="Low",1,0)))) -> 3 | N40: 0 | O40: =IF(N40="",IF(I40="Closed Out",1,IF(I40="Complete",1,IF(I40="Approved",1,IF(I40="Reviewed",1,IF(I40="In Review",0.9,IF(I40="75% Complete",0.75,IF(I40="50% Complete",0.5,IF(I40="25% Complete",0.25,IF(I40="Started",0.25,0))))))))),MAX(IF(I40="Closed Out",1,IF(I40="Complete",1,IF(I40="Approved",1,IF(I40="Reviewed",1,IF(I40="In Review",0.9,IF(I40="75% Complete",0.75,IF(I40="50% Complete",0.5,IF(I40="25% Complete",0.25,IF(I40="Started",0.25,0))))))))),N40)) -> 0 | P40: =M40*O40 -> 0 | Q40: =IF(OR(I40="Closed Out",I40="Complete",I40="Approved",I40="Reviewed"),"Closed",IF(OR(I40="HOLD",I40="Pause"),"Blocked","Open")) -> Blocked | R40: =IF(AND(Q40="Open",ISNUMBER(L40),L40<TODAY()),1,0) -> 0 | S40: 0 | V40: =IF(ISNUMBER(L40),"Q"&ROUNDUP(MONTH(L40)/3,0),IF(LEFT(TRIM(CLEAN(L40)),1)="Q","Q"&VALUE(RIGHT(TRIM(CLEAN(L40)),1)),"No Date")) -> No Date
...

Sheet Executive Dashboard
A1: E&I Department Action Item Tracker
A2: Current action-item list data tracker.
A4: Total Tasks | D4: Current Weighted Scope | G4: Current Weighted Earned | J4: Current Weighted Progress
A5: =COUNTA('Initiative List'!A:A)-1 -> 134 | D5: =SUM('Initiative List'!M:M) -> 305 | G5: =SUM('Initiative List'!P:P) -> 135.25 | J5: =IFERROR(G5/D5,0) -> 0.44344262 | M5: Current Quarter Focus
M6: Current Quarter Weighted Scope | N6: =SUMIF('Initiative List'!V:V,TRIM(J9),'Initiative List'!M:M) -> 63
M7: Current Quarter Weighted Earned | N7: =SUMIF('Initiative List'!V:V,TRIM(J9),'Initiative List'!P:P) -> 17.35
A8: Overdue Open Items | D8: Blocked Items | G8: Closed Items | J8: Current Quarter | M8: Current Quarter Weighted % | N8: =IFERROR(N7/N6,0) -> 0.27539683
A9: =SUM('Initiative List'!R:R) -> 11 | D9: =COUNTIF('Initiative List'!Q:Q,"Blocked") -> 41 | G9: =COUNTIF('Initiative List'!Q:Q,"Closed") -> 41 | J9: =_xlfn.SINGLE(_xlfn.CONCAT("Q",ROUNDUP(MONTH(TODAY())/3,0))) -> Q3 | M9: Current Quarter Task Count | N9: =COUNTIF('Initiative List'!V:V,J9) -> 40
A13: Weekly Trend | F13: Weight Definition
A14: Week Ending | B14: Actual Cum % | C14: Actual Earned | D14: Weekly Actual Earned | F14: Priority | G14: Weight | H14: Tasks | I14: Completed Tasks | J14: % Complete
A15: ='Weekly Tracking'!A2 -> 46157 | B15: ='Weekly Tracking'!D2 -> 0.16460905 | C15: ='Weekly Tracking'!E2 -> 40 | D15: ='Weekly Tracking'!H2 -> 40 | F15: Critical | G15: 4 | H15: =COUNTIF('Initiative List'!K:K,F15) -> 28 | I15: =COUNTIFS('Initiative List'!K:K,'Executive Dashboard'!F15,'Initiative List'!I:I, "Closed Out")+COUNTIFS('Initiative List'!K:K,'Executive Dashboard'!F15,'Initiative List'!I:I, "Completed") -> 17 | J15: =I15/H15 -> 0.60714286
A16: ='Weekly Tracking'!A3 -> 46164 | B16: ='Weekly Tracking'!D3 -> 0.17695473 | C16: ='Weekly Tracking'!E3 -> 43 | D16: ='Weekly Tracking'!H3 -> 3 | F16: High | G16: 3 | H16: =COUNTIF('Initiative List'!K:K,F16) -> 39 | I16: =COUNTIFS('Initiative List'!K:K,'Executive Dashboard'!F16,'Initiative List'!I:I, "Closed Out")+COUNTIFS('Initiative List'!K:K,'Executive Dashboard'!F16,'Initiative List'!I:I, "Completed") -> 6 | J16: =I16/H16 -> 0.15384615
A17: ='Weekly Tracking'!A4 -> 46171 | B17: ='Weekly Tracking'!D4 -> 0.17695473 | C17: ='Weekly Tracking'!E4 -> 43 | D17: ='Weekly Tracking'!H4 -> 0 | F17: Medium | G17: 2 | H17: =COUNTIF('Initiative List'!K:K,F17) -> 13 | I17: =COUNTIFS('Initiative List'!K:K,'Executive Dashboard'!F17,'Initiative List'!I:I, "Closed Out")+COUNTIFS('Initiative List'!K:K,'Executive Dashboard'!F17,'Initiative List'!I:I, "Completed") -> 0 | J17: =I17/H17 -> 0
A18: ='Weekly Tracking'!A5 -> 46178 | B18: ='Weekly Tracking'!D5 -> 0.17695473 | C18: ='Weekly Tracking'!E5 -> 43 | D18: ='Weekly Tracking'!H5 -> 0 | F18: Low | G18: 1 | H18: =COUNTIF('Initiative List'!K:K,F18) -> 52 | I18: =COUNTIFS('Initiative List'!K:K,'Executive Dashboard'!F18,'Initiative List'!I:I, "Closed Out")+COUNTIFS('Initiative List'!K:K,'Executive Dashboard'!F18,'Initiative List'!I:I, "Completed") -> 15 | J18: =I18/H18 -> 0.28846154
A19: ='Weekly Tracking'!A6 -> 46185 | B19: ='Weekly Tracking'!D6 -> 0.1877551 | C19: ='Weekly Tracking'!E6 -> 46 | D19: ='Weekly Tracking'!H6 -> 3
A20: ='Weekly Tracking'!A7 -> 46192 | B20: ='Weekly Tracking'!D7 -> 0.29770492 | C20: ='Weekly Tracking'!E7 -> 90.8 | D20: ='Weekly Tracking'!H7 -> 44.8
A21: ='Weekly Tracking'!A8 -> 46199 | B21: ='Weekly Tracking'!D8 -> 0.43836066 | C21: ='Weekly Tracking'!E8 -> 133.7 | D21: ='Weekly Tracking'!H8 -> 42.9
A22: ='Weekly Tracking'!A9 -> 46206 | B22: ='Weekly Tracking'!D9 -> 0.44 | C22: ='Weekly Tracking'!E9 -> 134.2 | D22: ='Weekly Tracking'!H9 -> 0.5
A23: ='Weekly Tracking'!A10 -> 46213 | B23: ='Weekly Tracking'!D10 -> 0.44344262 | C23: ='Weekly Tracking'!E10 -> 135.25 | D23: ='Weekly Tracking'!H10 -> 1.05
A24: ='Weekly Tracking'!A11 -> 46220 | B24: ='Weekly Tracking'!D11 -> 0.44344262 | C24: ='Weekly Tracking'!E11 -> 135.25 | D24: ='Weekly Tracking'!H11 -> 0
A25: ='Weekly Tracking'!A12 -> 46227 | B25: ='Weekly Tracking'!D12 -> 0.44344262 | C25: ='Weekly Tracking'!E12 -> 135.25 | D25: ='Weekly Tracking'!H12 -> 0
A26: ='Weekly Tracking'!A13 -> 46234 | B26: ='Weekly Tracking'!D13 -> 0.44344262 | C26: ='Weekly Tracking'!E13 -> 135.25 | D26: ='Weekly Tracking'!H13 -> 0
A29: WEEKLY NARRATIVE | H29: Categories
A30: This Week Progress: | H30: Initiative | I30: Task Count | J30: Weighted Scope | K30: Weighted Earned | L30: % Complete | M30: % Overall of Categories
A31: - Significant progress achieved in Energy Standardization and Grounding initiatives. | H31: {=_xlfn.UNIQUE('Initiative List'!B2:B1017)} -> Consistency Workshop | I31: =COUNTIF('Initiative List'!B:B,'Executive Dashboard'!H31) -> 39 | J31: =SUMIF('Initiative List'!B:B,'Executive Dashboard'!H31, 'Initiative List'!M:M) -> 103 | K31: =SUMIF('Initiative List'!B:B,'Executive Dashboard'!H31, 'Initiative List'!P:P) -> 12.4 | L31: =IFERROR(K31/J31,0) -> 0.12038835 | M31: =J31/SUM($J$31:$J$53) -> 0.33770492
A32: - Weighted earned increased due to multiple In Review items approaching completion. | H32: Estimate Document Numbering | I32: =COUNTIF('Initiative List'!B:B,'Executive Dashboard'!H32) -> 2 | J32: =SUMIF('Initiative List'!B:B,'Executive Dashboard'!H32, 'Initiative List'!M:M) -> 6 | K32: =SUMIF('Initiative List'!B:B,'Executive Dashboard'!H32, 'Initiative List'!P:P) -> 0 | L32: =IFERROR(K32/J32,0) -> 0 | M32: =J32/SUM($J$31:$J$53) -> 0.019672131
H33: Indicative Tool | I33: =COUNTIF('Initiative List'!B:B,'Executive Dashboard'!H33) -> 8 | J33: =SUMIF('Initiative List'!B:B,'Executive Dashboard'!H33, 'Initiative List'!M:M) -> 21 | K33: =SUMIF('Initiative List'!B:B,'Executive Dashboard'!H33, 'Initiative List'!P:P) -> 19.9 | L33: =IFERROR(K33/J33,0) -> 0.94761905 | M33: =J33/SUM($J$31:$J$53) -> 0.068852459
H34: Initiatives - Future | I34: =COUNTIF('Initiative List'!B:B,'Executive Dashboard'!H34) -> 6 | J34: =SUMIF('Initiative List'!B:B,'Executive Dashboard'!H34, 'Initiative List'!M:M) -> 12 | K34: =SUMIF('Initiative List'!B:B,'Executive Dashboard'!H34, 'Initiative List'!P:P) -> 5.3 | L34: =IFERROR(K34/J34,0) -> 0.44166667 | M34: =J34/SUM($J$31:$J$53) -> 0.039344262
A35: Key Drivers: | H35: Mock Project Files | I35: =COUNTIF('Initiative List'!B:B,'Executive Dashboard'!H35) -> 1 | J35: =SUMIF('Initiative List'!B:B,'Executive Dashboard'!H35, 'Initiative List'!M:M) -> 1 | K35: =SUMIF('Initiative List'!B:B,'Executive Dashboard'!H35, 'Initiative List'!P:P) -> 0 | L35: =IFERROR(K35/J35,0) -> 0 | M35: =J35/SUM($J$31:$J$53) -> 0.0032786885
A36: - Electrical Grounding and Energy procedures advancing steadily. | H36: I&C Adapt Logic | I36: =COUNTIF('Initiative List'!B:B,'Executive Dashboard'!H36) -> 5 | J36: =SUMIF('Initiative List'!B:B,'Executive Dashboard'!H36, 'Initiative List'!M:M) -> 7 | K36: =SUMIF('Initiative List'!B:B,'Executive Dashboard'!H36, 'Initiative List'!P:P) -> 6 | L36: =IFERROR(K36/J36,0) -> 0.85714286 | M36: =J36/SUM($J$31:$J$53) -> 0.02295082
A37: - Multiple initiatives transitioned from Started → In Review → nearing closure. | H37: Department Display | I37: =COUNTIF('Initiative List'!B:B,'Executive Dashboard'!H37) -> 1 | J37: =SUMIF('Initiative List'!B:B,'Executive Dashboard'!H37, 'Initiative List'!M:M) -> 1 | K37: =SUMIF('Initiative List'!B:B,'Executive Dashboard'!H37, 'Initiative List'!P:P) -> 0 | L37: =IFERROR(K37/J37,0) -> 0 | M37: =J37/SUM($J$31:$J$53) -> 0.0032786885
H38: White Paper Reports | I38: =COUNTIF('Initiative List'!B:B,'Executive Dashboard'!H38) -> 3 | J38: =SUMIF('Initiative List'!B:B,'Executive Dashboard'!H38, 'Initiative List'!M:M) -> 12 | K38: =SUMIF('Initiative List'!B:B,'Executive Dashboard'!H38, 'Initiative List'!P:P) -> 3.6 | L38: =IFERROR(K38/J38,0) -> 0.3 | M38: =J38/SUM($J$31:$J$53) -> 0.039344262
A39: Risks / Blockers: | H39: Initiatives Folder | I39: =COUNTIF('Initiative List'!B:B,'Executive Dashboard'!H39) -> 3 | J39: =SUMIF('Initiative List'!B:B,'Executive Dashboard'!H39, 'Initiative List'!M:M) -> 5 | K39: =SUMIF('Initiative List'!B:B,'Executive Dashboard'!H39, 'Initiative List'!P:P) -> 4.9 | L39: =IFERROR(K39/J39,0) -> 0.98 | M39: =J39/SUM($J$31:$J$53) -> 0.016393443
A40: - Large volume of Consistency Workshop ADAPT-related items remain on HOLD. | H40: Energy Standardization | I40: =COUNTIF('Initiative List'!B:B,'Executive Dashboard'!H40) -> 36 | J40: =SUMIF('Initiative List'!B:B,'Executive Dashboard'!H40, 'Initiative List'!M:M) -> 93 | K40: =SUMIF('Initiative List'!B:B,'Executive Dashboard'!H40, 'Initiative List'!P:P) -> 53.75 | L40: =IFERROR(K40/J40,0) -> 0.57795699 | M40: =J40/SUM($J$31:$J$53) -> 0.30491803
A41: - These blocked tasks represent a large portion of remaining weighted scope. | H41: Vendor Presentations | I41: =COUNTIF('Initiative List'!B:B,'Executive Dashboard'!H41) -> 3 | J41: =SUMIF('Initiative List'!B:B,'Executive Dashboard'!H41, 'Initiative List'!M:M) -> 3 | K41: =SUMIF('Initiative List'!B:B,'Executive Dashboard'!H41, 'Initiative List'!P:P) -> 2.65 | L41: =IFERROR(K41/J41,0) -> 0.88333333 | M41: =J41/SUM($J$31:$J$53) -> 0.0098360656
H42: Temporary Power | I42: =COUNTIF('Initiative List'!B:B,'Executive Dashboard'!H42) -> 1 | J42: =SUMIF('Initiative List'!B:B,'Executive Dashboard'!H42, 'Initiative List'!M:M) -> 4 | K42: =SUMIF('Initiative List'!B:B,'Executive Dashboard'!H42, 'Initiative List'!P:P) -> 4 | L42: =IFERROR(K42/J42,0) -> 1 | M42: =J42/SUM($J$31:$J$53) -> 0.013114754
